<?xml version='1.0'?>
<sdf version='1.4'>
  <model name="my_robot">
    <static>false</static>
      <link name='chassis'>
            <pose>0 0 .1 0 0 0</pose>

            <collision name='collision'>
              <geometry>
                <box>
                  <size>.4 .2 .1</size>
                </box>
              </geometry>
            </collision>

            <visual name='visual'>
              <geometry>
                <box>
                  <size>.4 .2 .1</size>
                </box>
              </geometry>
            </visual>

          </link>
      <link name="left_front_wheel">
        <pose>0.1 0.13 0.075 0 1.5707 1.5707</pose>
        <collision name="collision">
          <geometry>
            <cylinder>
              <radius>.075</radius>
              <length>.05</length>
            </cylinder>
          </geometry>
        </collision>
        <visual name="visual">
          <geometry>
            <cylinder>
              <radius>.075</radius>
              <length>.05</length>
            </cylinder>
          </geometry>
        </visual>
      </link>
      <link name="right_front_wheel">
        <pose>0.1 -0.13 0.075 0 1.5707 1.5707</pose>
        <collision name="collision">
          <geometry>
            <cylinder>
              <radius>.075</radius>
              <length>.075</length>
            </cylinder>
          </geometry>
        </collision>
        <visual name="visual">
          <geometry>
            <cylinder>
              <radius>.075</radius>
              <length>.075</length>
            </cylinder>
          </geometry>
        </visual>
      </link>
      <joint type="revolute" name="left_front_wheel_hinge">
        <pose>0 0 -0.03 0 0 0</pose>
        <child>left_front_wheel</child>
        <parent>chassis</parent>
        <axis>
          <xyz>0 1 0</xyz>
        </axis>
      </joint>

      <joint type="revolute" name="right_front_wheel_hinge">
        <pose>0 0 0.03 0 0 0</pose>
        <child>right_front_wheel</child>
        <parent>chassis</parent>
        <axis>
          <xyz>0 1 0</xyz>
        </axis>
      </joint>




      <link name="left_back_wheel">
        <pose>-0.1 0.13 0.075 0 1.5707 1.5707</pose>
        <collision name="collision">
          <geometry>
            <cylinder>
              <radius>.075</radius>
              <length>.075</length>
            </cylinder>
          </geometry>
        </collision>
        <visual name="visual">
          <geometry>
            <cylinder>
              <radius>.075</radius>
              <length>.075</length>
            </cylinder>
          </geometry>
        </visual>
      </link>
      <link name="right_back_wheel">
        <pose>-0.1 -0.13 0.075 0 1.5707 1.5707</pose>
        <collision name="collision">
          <geometry>
            <cylinder>
              <radius>.075</radius>
              <length>.075</length>
            </cylinder>
          </geometry>
        </collision>
        <visual name="visual">
          <geometry>
            <cylinder>
              <radius>.075</radius>
              <length>.075</length>
            </cylinder>
          </geometry>
        </visual>
      </link>
      <joint type="revolute" name="left_back_wheel_hinge">
        <pose>0 0 -0.03 0 0 0</pose>
        <child>left_back_wheel</child>
        <parent>chassis</parent>
        <axis>
          <xyz>0 1 0</xyz>
        </axis>
      </joint>

      <joint type="revolute" name="right_back_wheel_hinge">
        <pose>0 0 0.03 0 0 0</pose>
        <child>right_back_wheel</child>
        <parent>chassis</parent>
        <axis>
          <xyz>0 1 0</xyz>
        </axis>
      </joint>
  </model>
</sdf>
