<?xml version="1.0" ?>
<robot name="Untitled">
  
  <gazebo>
    <plugin name="gazebo_ros_control" filename="libgazebo_ros_control.so">
      <robotNamespace>/monoped</robotNamespace>
      <robotParam>$(find theShit)/robot/Untitled/model.urdf</robotParam>
    </plugin>
  </gazebo>

  <joint name="Untitled__link_0_JOINT_4" type="fixed">
    <parent link="Untitled__link_0"/>
    <child link="Untitled__link_1"/>
    <origin xyz="-8.0000e-05 -3.5000e-04 -1.4644e-01" rpy="0 0 0"/>
    <axis xyz="0 0 0"/>
    <limit lower="0" upper="0" effort="0" velocity="0"/>
  </joint>
  <joint name="Untitled__link_2_JOINT_3" type="revolute">
    <parent link="Untitled__link_2"/>
    <child link="Untitled__link_0"/>
    <origin xyz="0.00036 -0.00059 -0.28218" rpy="0 0 0"/>
    <axis xyz="1 0 0"/>
    <limit lower="-1.79769e+308" upper="1.79769e+308" effort="-1.0" velocity="-1.0"/>
  </joint>
  <joint name="Untitled__link_3_JOINT_2" type="revolute">
    <parent link="Untitled__link_3"/>
    <child link="Untitled__link_2"/>
    <origin xyz="0.03248 0.01928 0.22066" rpy="0 0 0"/>
    <axis xyz="1 0 0"/>
    <limit lower="-1.79769e+308" upper="1.79769e+308" effort="-1.0" velocity="-1.0"/>
  </joint>
  <link name="Untitled__link_0">
    <inertial>
      <mass value="9.19959e-05"/>
      <origin xyz="0 0 0" rpy="0 0 0"/>
      <inertia ixx="1.83419e-07" ixy="0" ixz="0" iyy="1.83419e-07" iyz="0" izz="7.00448e-09"/>
    </inertial>
    <collision name="Untitled__collision">
      <origin xyz="0    0   -0.07" rpy="0 0 0"/>
      <geometry>
        <cylinder radius="0.01234" length="0.153194"/>
      </geometry>
    </collision>
    <visual name="Untitled__visual">
      <origin xyz="0    0   -0.07" rpy="0 0 0"/>
      <geometry>
        <cylinder radius="0.0123401" length="0.153194"/>
      </geometry>
    </visual>
  </link>
  <link name="Untitled__link_1">
    <inertial>
      <mass value="0.00017202"/>
      <origin xyz="0 0 0" rpy="0 0 0"/>
      <inertia ixx="5e-08" ixy="0" ixz="0" iyy="5e-08" iyz="0" izz="5e-08"/>
    </inertial>
    <collision name="Untitled__collision">
      <origin xyz="0 0 0" rpy="0 0 0"/>
      <geometry>
        <sphere radius="0.027859"/>
      </geometry>
    </collision>
    <visual name="Untitled__visual">
      <origin xyz="0 0 0" rpy="0 0 0"/>
      <geometry>
        <sphere radius="0.0278585"/>
      </geometry>
    </visual>
  </link>
  <link name="Untitled__link_2">
    <inertial>
      <mass value="0.000304883"/>
      <origin xyz="0 0 0" rpy="0 0 0"/>
      <inertia ixx="2.62227e-06" ixy="0" ixz="0" iyy="2.62227e-06" iyz="0" izz="3.61222e-08"/>
    </inertial>
    <collision name="Untitled__collision">
      <origin xyz="0    0   -0.13" rpy="0 0 0"/>
      <geometry>
        <cylinder radius="0.015393" length="0.320156"/>
      </geometry>
    </collision>
    <visual name="Untitled__visual">
      <origin xyz="0    0   -0.13" rpy="0 0 0"/>
      <geometry>
        <cylinder radius="0.0153934" length="0.320156"/>
      </geometry>
    </visual>
  </link>
  <link name="Untitled__link_3">
    <inertial>
      <mass value="0.00462081"/>
      <origin xyz="0 0 0" rpy="0 0 0"/>
      <inertia ixx="1.22756e-05" ixy="0" ixz="0" iyy="3.83549e-05" iyz="0" izz="3.86014e-05"/>
    </inertial>
    <collision name="Untitled__collision">
      <origin xyz="-0.11718  0.00076  0.28066" rpy="0 0 0"/>
      <geometry>
        <box size="0.289804 0.127513 0.124978"/>
      </geometry>
    </collision>
    <visual name="Untitled__visual">
      <origin xyz="-0.11718  0.00076  0.28066" rpy="0 0 0"/>
      <geometry>
        <box size="0.289804 0.127513 0.124978"/>
      </geometry>
    </visual>
  </link>
  
  <transmission name="trans_joint_2">
    <type>transmission_interface/SimpleTransmission</type>
    <joint name="Untitled__link_3_JOINT_2">
      <hardwareInterface>hardware_interface/EffortJointInterface</hardwareInterface>
    </joint>
    <actuator name="joint_2Motor">
      <hardwareInterface>hardware_interface/EffortJointInterface</hardwareInterface>
      <mechanicalReduction>1</mechanicalReduction>
    </actuator>
  </transmission>
  
  <transmission name="trans_joint_3">
    <type>transmission_interface/SimpleTransmission</type>
    <joint name="Untitled__link_2_JOINT_3">
      <hardwareInterface>hardware_interface/EffortJointInterface</hardwareInterface>
    </joint>
    <actuator name="joint_3Motor">
      <hardwareInterface>hardware_interface/EffortJointInterface</hardwareInterface>
      <mechanicalReduction>1</mechanicalReduction>
    </actuator>
  </transmission> 

</robot>
